2019-08-23 11:59:35.889564: I tensorflow/core/platform/cpu_feature_guard.cc:141] Your CPU supports instructions that this TensorFlow binary was not compiled to use: AVX2 AVX512F FMA
2019-08-23 11:59:40.074515: I tensorflow/core/common_runtime/gpu/gpu_device.cc:1432] Found device 0 with properties: 
name: Tesla P100-PCIE-16GB major: 6 minor: 0 memoryClockRate(GHz): 1.3285
pciBusID: 0000:5a:00.0
totalMemory: 15.89GiB freeMemory: 15.60GiB
2019-08-23 11:59:40.334669: I tensorflow/core/common_runtime/gpu/gpu_device.cc:1432] Found device 1 with properties: 
name: Tesla P100-PCIE-16GB major: 6 minor: 0 memoryClockRate(GHz): 1.3285
pciBusID: 0000:5e:00.0
totalMemory: 15.89GiB freeMemory: 15.60GiB
2019-08-23 11:59:40.621669: I tensorflow/core/common_runtime/gpu/gpu_device.cc:1432] Found device 2 with properties: 
name: Tesla P100-PCIE-16GB major: 6 minor: 0 memoryClockRate(GHz): 1.3285
pciBusID: 0000:62:00.0
totalMemory: 15.89GiB freeMemory: 15.60GiB
2019-08-23 11:59:40.910374: I tensorflow/core/common_runtime/gpu/gpu_device.cc:1432] Found device 3 with properties: 
name: Tesla P100-PCIE-16GB major: 6 minor: 0 memoryClockRate(GHz): 1.3285
pciBusID: 0000:66:00.0
totalMemory: 15.89GiB freeMemory: 15.60GiB
2019-08-23 11:59:40.922225: I tensorflow/core/common_runtime/gpu/gpu_device.cc:1511] Adding visible gpu devices: 0, 1, 2, 3
2019-08-23 11:59:46.025460: I tensorflow/core/common_runtime/gpu/gpu_device.cc:982] Device interconnect StreamExecutor with strength 1 edge matrix:
2019-08-23 11:59:46.025582: I tensorflow/core/common_runtime/gpu/gpu_device.cc:988]      0 1 2 3 
2019-08-23 11:59:46.025640: I tensorflow/core/common_runtime/gpu/gpu_device.cc:1001] 0:   N Y Y Y 
2019-08-23 11:59:46.025691: I tensorflow/core/common_runtime/gpu/gpu_device.cc:1001] 1:   Y N Y Y 
2019-08-23 11:59:46.025741: I tensorflow/core/common_runtime/gpu/gpu_device.cc:1001] 2:   Y Y N Y 
2019-08-23 11:59:46.025791: I tensorflow/core/common_runtime/gpu/gpu_device.cc:1001] 3:   Y Y Y N 
2019-08-23 11:59:46.027757: I tensorflow/core/common_runtime/gpu/gpu_device.cc:1115] Created TensorFlow device (/job:localhost/replica:0/task:0/device:GPU:0 with 15117 MB memory) -> physical GPU (device: 0, name: Tesla P100-PCIE-16GB, pci bus id: 0000:5a:00.0, compute capability: 6.0)
2019-08-23 11:59:46.031782: I tensorflow/core/common_runtime/gpu/gpu_device.cc:1115] Created TensorFlow device (/job:localhost/replica:0/task:0/device:GPU:1 with 15117 MB memory) -> physical GPU (device: 1, name: Tesla P100-PCIE-16GB, pci bus id: 0000:5e:00.0, compute capability: 6.0)
2019-08-23 11:59:46.032694: I tensorflow/core/common_runtime/gpu/gpu_device.cc:1115] Created TensorFlow device (/job:localhost/replica:0/task:0/device:GPU:2 with 15117 MB memory) -> physical GPU (device: 2, name: Tesla P100-PCIE-16GB, pci bus id: 0000:62:00.0, compute capability: 6.0)
2019-08-23 11:59:46.033440: I tensorflow/core/common_runtime/gpu/gpu_device.cc:1115] Created TensorFlow device (/job:localhost/replica:0/task:0/device:GPU:3 with 15117 MB memory) -> physical GPU (device: 3, name: Tesla P100-PCIE-16GB, pci bus id: 0000:66:00.0, compute capability: 6.0)
/zfssz2/ST_MCHRI/BIGDATA/USER/baiyong/anaconda3/lib/python3.6/site-packages/h5py/__init__.py:36: FutureWarning: Conversion of the second argument of issubdtype from `float` to `np.floating` is deprecated. In future, it will be treated as `np.float64 == np.dtype(float).type`.
  from ._conv import register_converters as _register_converters
Using TensorFlow backend.
Traceback (most recent call last):
  File "/zfssz2/ST_MCHRI/BIGDATA/USER/baiyong/anaconda3/lib/python3.6/site-packages/tensorflow/python/client/session.py", line 1334, in _do_call
    return fn(*args)
  File "/zfssz2/ST_MCHRI/BIGDATA/USER/baiyong/anaconda3/lib/python3.6/site-packages/tensorflow/python/client/session.py", line 1319, in _run_fn
    options, feed_dict, fetch_list, target_list, run_metadata)
  File "/zfssz2/ST_MCHRI/BIGDATA/USER/baiyong/anaconda3/lib/python3.6/site-packages/tensorflow/python/client/session.py", line 1407, in _call_tf_sessionrun
    run_metadata)
tensorflow.python.framework.errors_impl.InvalidArgumentError: Nan in summary histogram for: batch_normalization_10/moving_variance_0
	 [[{{node batch_normalization_10/moving_variance_0}} = HistogramSummary[T=DT_FLOAT, _device="/job:localhost/replica:0/task:0/device:CPU:0"](batch_normalization_10/moving_variance_0/tag, batch_normalization_10/moving_variance/read/_8941)]]
	 [[{{node dense_17/kernel/read/_10253}} = _Recv[client_terminated=false, recv_device="/job:localhost/replica:0/task:0/device:GPU:3", send_device="/job:localhost/replica:0/task:0/device:GPU:0", send_device_incarnation=1, tensor_name="edge_8919_dense_17/kernel/read", tensor_type=DT_FLOAT, _device="/job:localhost/replica:0/task:0/device:GPU:3"]()]]

During handling of the above exception, another exception occurred:

Traceback (most recent call last):
  File "model_train_main.py", line 35, in <module>
    train(x_train, y_train, model_root_dir)
  File "/zfssz2/ST_MCHRI/BIGDATA/USER/baiyong/cnv_detect_final/train_model/train_run.py", line 67, in train
    epochs=epochs, batch_size=batch, callbacks=callbacks)
  File "/zfssz2/ST_MCHRI/BIGDATA/USER/baiyong/anaconda3/lib/python3.6/site-packages/keras/engine/training.py", line 1039, in fit
    validation_steps=validation_steps)
  File "/zfssz2/ST_MCHRI/BIGDATA/USER/baiyong/anaconda3/lib/python3.6/site-packages/keras/engine/training_arrays.py", line 217, in fit_loop
    callbacks.on_epoch_end(epoch, epoch_logs)
  File "/zfssz2/ST_MCHRI/BIGDATA/USER/baiyong/anaconda3/lib/python3.6/site-packages/keras/callbacks.py", line 79, in on_epoch_end
    callback.on_epoch_end(epoch, logs)
  File "/zfssz2/ST_MCHRI/BIGDATA/USER/baiyong/anaconda3/lib/python3.6/site-packages/keras/callbacks.py", line 941, in on_epoch_end
    result = self.sess.run([self.merged], feed_dict=feed_dict)
  File "/zfssz2/ST_MCHRI/BIGDATA/USER/baiyong/anaconda3/lib/python3.6/site-packages/tensorflow/python/client/session.py", line 929, in run
    run_metadata_ptr)
  File "/zfssz2/ST_MCHRI/BIGDATA/USER/baiyong/anaconda3/lib/python3.6/site-packages/tensorflow/python/client/session.py", line 1152, in _run
    feed_dict_tensor, options, run_metadata)
  File "/zfssz2/ST_MCHRI/BIGDATA/USER/baiyong/anaconda3/lib/python3.6/site-packages/tensorflow/python/client/session.py", line 1328, in _do_run
    run_metadata)
  File "/zfssz2/ST_MCHRI/BIGDATA/USER/baiyong/anaconda3/lib/python3.6/site-packages/tensorflow/python/client/session.py", line 1348, in _do_call
    raise type(e)(node_def, op, message)
tensorflow.python.framework.errors_impl.InvalidArgumentError: Nan in summary histogram for: batch_normalization_10/moving_variance_0
	 [[node batch_normalization_10/moving_variance_0 (defined at /zfssz2/ST_MCHRI/BIGDATA/USER/baiyong/anaconda3/lib/python3.6/site-packages/keras/callbacks.py:796)  = HistogramSummary[T=DT_FLOAT, _device="/job:localhost/replica:0/task:0/device:CPU:0"](batch_normalization_10/moving_variance_0/tag, batch_normalization_10/moving_variance/read/_8941)]]
	 [[{{node dense_17/kernel/read/_10253}} = _Recv[client_terminated=false, recv_device="/job:localhost/replica:0/task:0/device:GPU:3", send_device="/job:localhost/replica:0/task:0/device:GPU:0", send_device_incarnation=1, tensor_name="edge_8919_dense_17/kernel/read", tensor_type=DT_FLOAT, _device="/job:localhost/replica:0/task:0/device:GPU:3"]()]]

Caused by op 'batch_normalization_10/moving_variance_0', defined at:
  File "model_train_main.py", line 35, in <module>
    train(x_train, y_train, model_root_dir)
  File "/zfssz2/ST_MCHRI/BIGDATA/USER/baiyong/cnv_detect_final/train_model/train_run.py", line 67, in train
    epochs=epochs, batch_size=batch, callbacks=callbacks)
  File "/zfssz2/ST_MCHRI/BIGDATA/USER/baiyong/anaconda3/lib/python3.6/site-packages/keras/engine/training.py", line 1039, in fit
    validation_steps=validation_steps)
  File "/zfssz2/ST_MCHRI/BIGDATA/USER/baiyong/anaconda3/lib/python3.6/site-packages/keras/engine/training_arrays.py", line 117, in fit_loop
    callbacks.set_model(callback_model)
  File "/zfssz2/ST_MCHRI/BIGDATA/USER/baiyong/anaconda3/lib/python3.6/site-packages/keras/callbacks.py", line 54, in set_model
    callback.set_model(model)
  File "/zfssz2/ST_MCHRI/BIGDATA/USER/baiyong/anaconda3/lib/python3.6/site-packages/keras/callbacks.py", line 796, in set_model
    tf.summary.histogram(mapped_weight_name, weight)
  File "/zfssz2/ST_MCHRI/BIGDATA/USER/baiyong/anaconda3/lib/python3.6/site-packages/tensorflow/python/summary/summary.py", line 187, in histogram
    tag=tag, values=values, name=scope)
  File "/zfssz2/ST_MCHRI/BIGDATA/USER/baiyong/anaconda3/lib/python3.6/site-packages/tensorflow/python/ops/gen_logging_ops.py", line 284, in histogram_summary
    "HistogramSummary", tag=tag, values=values, name=name)
  File "/zfssz2/ST_MCHRI/BIGDATA/USER/baiyong/anaconda3/lib/python3.6/site-packages/tensorflow/python/framework/op_def_library.py", line 787, in _apply_op_helper
    op_def=op_def)
  File "/zfssz2/ST_MCHRI/BIGDATA/USER/baiyong/anaconda3/lib/python3.6/site-packages/tensorflow/python/util/deprecation.py", line 488, in new_func
    return func(*args, **kwargs)
  File "/zfssz2/ST_MCHRI/BIGDATA/USER/baiyong/anaconda3/lib/python3.6/site-packages/tensorflow/python/framework/ops.py", line 3274, in create_op
    op_def=op_def)
  File "/zfssz2/ST_MCHRI/BIGDATA/USER/baiyong/anaconda3/lib/python3.6/site-packages/tensorflow/python/framework/ops.py", line 1770, in __init__
    self._traceback = tf_stack.extract_stack()

InvalidArgumentError (see above for traceback): Nan in summary histogram for: batch_normalization_10/moving_variance_0
	 [[node batch_normalization_10/moving_variance_0 (defined at /zfssz2/ST_MCHRI/BIGDATA/USER/baiyong/anaconda3/lib/python3.6/site-packages/keras/callbacks.py:796)  = HistogramSummary[T=DT_FLOAT, _device="/job:localhost/replica:0/task:0/device:CPU:0"](batch_normalization_10/moving_variance_0/tag, batch_normalization_10/moving_variance/read/_8941)]]
	 [[{{node dense_17/kernel/read/_10253}} = _Recv[client_terminated=false, recv_device="/job:localhost/replica:0/task:0/device:GPU:3", send_device="/job:localhost/replica:0/task:0/device:GPU:0", send_device_incarnation=1, tensor_name="edge_8919_dense_17/kernel/read", tensor_type=DT_FLOAT, _device="/job:localhost/replica:0/task:0/device:GPU:3"]()]]

